<?xml version="1.0"?>

<robot name="ddbot">

    <link name="base_footprint"/>

    <material name="grey">
        <color rgba="0.82 0.82 0.82 1.0"/>
    </material>

    <material name="black">
        <color rgba="0.2 0.2 0.2 1.0"/>
    </material>

    <gazebo reference="base_link">
        <material>Gazebo/Grey</material>
    </gazebo>

    <gazebo reference="front_left_wheel_joint">
        <material>Gazebo/DarkGrey</material>
    </gazebo>

    <gazebo reference="front_right_wheel_joint">
        <material>Gazebo/DarkGrey</material>
    </gazebo>

    <link name="base_link">
        <visual>
            <geometry>
                <mesh filename="package://ddbot_description/meshes/body.stl" scale="0.001 0.001 0.001"/>
            </geometry>
            <origin rpy="1.570796 0 0" xyz="0.0375 0 0.009"/>
            <material name="grey"/>
        </visual>
        <collision>
            <geometry>
                <mesh filename="package://ddbot_description/meshes/body.stl" scale="0.001 0.001 0.001"/>
            </geometry>
            <origin rpy="1.570796 0 0" xyz="0.0375 0 0.009"/>
        </collision>
        <inertial>
            <origin rpy="1.570796 0 0" xyz="0.0375 0 0.009"/>
            <mass value="5.0"/>
            <inertia ixx="0.002747" ixy="0.0" ixz="0.0" iyy="0.004793" iyz="0.0" izz="0.007404"/> <!-- height = 3cm -->
        </inertial>
    </link>

    <link name="left_wheel">
        <visual>
            <geometry>
                <mesh filename="package://ddbot_description/meshes/wheel.stl" scale="0.001 0.001 0.001"/>
            </geometry>
            <origin rpy="0 0 4.712389" xyz="0 -0.01 0"/>
            <material name="black"/>
        </visual>
        <collision>
            <geometry>
                <cylinder length="0.016" radius="0.0254"/>
            </geometry>
            <origin rpy="1.57075 0 0" xyz="0 0 0"/>
        </collision>
        <inertial>
            <mass value="0.075"/>
            <inertia ixx="0.0000137" ixy="0.0" ixz="0.0" iyy="0.00002419" iyz="0.0" izz="0.0000137"/> <!-- height = 3cm -->
        </inertial>
    </link>

    <link name="right_wheel">
        <visual>
            <geometry>
                <mesh filename="package://ddbot_description/meshes/wheel.stl" scale="0.001 0.001 0.001"/>
            </geometry>
            <origin rpy="0 0 1.57075" xyz="0 0.01 0"/>
            <material name="black"/>
        </visual>
        <collision>
            <geometry>
                <cylinder length="0.016" radius="0.0254"/>
            </geometry>
            <origin rpy="1.57075 0 0" xyz="0 0 0"/>
        </collision>
        <inertial>
            <mass value="0.075"/>
            <inertia ixx="0.0000137" ixy="0.0" ixz="0.0" iyy="0.00002419" iyz="0.0" izz="0.0000137"/> <!-- height = 3cm -->
        </inertial>
    </link>


    <joint name="dummy_joint" type="fixed">
        <parent link="base_footprint"/>
        <child link="base_link"/>
        <origin rpy="0 0 0" xyz="0 0 0"/>
    </joint>

    <joint name="front_left_wheel_joint" type="continuous">
        <parent link="base_link"/>
        <child link="left_wheel"/>
        <origin xyz="0 0.111 0.0254"/>
        <axis xyz="0 1 0"/>
    </joint>

    <joint name="front_right_wheel_joint" type="continuous">
        <parent link="base_link"/>
        <child link="right_wheel"/>
        <origin xyz="0 -0.111 0.0254"/>
        <axis xyz="0 1 0"/>
    </joint>





    <transmission name="left_wheel_trans">
      <type>transmission_interface/SimpleTransmission</type>
      <actuator name="left_wheel_motor">
        <mechanicalReduction>1</mechanicalReduction>
      </actuator>
      <joint name="front_left_wheel_joint">
        <hardwareInterface>hardware_interface/VelocityJointInterface</hardwareInterface>
      </joint>
    </transmission>
    
    <transmission name="right_wheel_trans">
      <type>transmission_interface/SimpleTransmission</type>
      <actuator name="right_wheel_motor">
        <mechanicalReduction>1</mechanicalReduction>
      </actuator>
      <joint name="front_right_wheel_joint">
        <hardwareInterface>hardware_interface/VelocityJointInterface</hardwareInterface>
      </joint>
    </transmission>




    <!-- Gazebo plugin for ROS Control -->
    <gazebo>
        <plugin name="gazebo_ros_control" filename="libgazebo_ros_control.so">
            <robotNamespace>/diffbot</robotNamespace>
        </plugin>
    </gazebo>

</robot>